Workbook
Name SegmentaciónDeDatos_Clase_Del_Pasaje: #N/A
Name SegmentaciónDeDatos_Embarque: #N/A
Name SegmentaciónDeDatos_Sexo: #N/A

Sheet PORTADA
J1: Versión 1.0 — Marzo 2026
F2: ANÁLISIS DE SUPERVIVENCIA — TITANIC
F6: Trabájo Practico Final — Excel
F8: Matias Lieggi

Sheet README
A3: Dataset Extraído de Kaggle, con información sobre la tragedia del Titanic.
A4: 1.Se exporto el archivo CSV, a excel. Al copiar el dataset crudo, se utilizo la funcion Texto en columnas.
A5: 2.Al corroborar si había celdas vacías en cada columna, se detectó que las columnas Edad. Y Cabina tenian varios datos faltantes.
A6: 2.Para solucionar el error detectado en la columna Edad inserte una columna a la izquierda. Yutilice la formula : " =Si(ES.BLANCO(G2)ALEATORIO.ENTRE(1;80);G2) " y luego Copié y pegue los datos como Valor, para que no cambie constantemente dichos valores.
A7: 3.En el caso de la columna Cabina, habia muchisimos mas datos faltantes que en Edad. Y al tratarse de un dato distinto y mas complejo, Decidí utilizar la formula : " =SI(ESBLANCO(M2);"Desconocido";M2)) " insertando una columna a la izquierda y luego copiando los datos como valores
A8: 4.En el caso de la columna Fare, Precio: Tenia valores mixtos en formato Texto y Número. Siendo Precio de los pasajes, necesitamos el dato en Número. Entonces utilice la formula " =VALOR(SUSTITUIR;L2;".";",") " y asi logre tener todas las celdas con valor Número
A9: 5. En DATASET_CLEAN Re ordené las columnas de manera coherente. Y Reformulé los titulos de dichas columnas con los nombres al español.
A10: 6.Aplique Validación de datos en la columna Sexo y Embarque. En Sexo utilice como validación de datos tipo " Lista "y que los generos sean male ; female ( hombre ; mujer). En embarque también aplique formato Lista y que las opciones sean " S;C;Q "
A11: 7.Para la primer pregunta Calculé cantidades de pasarejos clasificados en " male " (hombres) y "female" (mujeres) utilizando Formula "=CONTAR.SI " luego calcule el porcentaje de hombres y mujeres sobre el total de pasarejos, utilizando CONTAR.SI / CONTARA y REDONDEAR.MAS REDONDEAR.MENOS
A12: 8.Me pregunté si existian diferencias entre la edad de pasarejos que sobrevivieron y los que no. Increiblemente la diferencia en promedio de edad de cada uno es minima. Y es por ello me abrió la incertidumbre a generar otra pregunta.
A13: 9. Dicha pregunta fue saber la tasa de supervivencia, de cada grupo etario: ( Niños, Jóvenes, Adultos y Adultos mayores). Al obtener estos datos utilizando formula " = CONTAR.SI.CONJUNTO" luego pude identificar y sacar una conclusión.
A14: 10. La conclusión que pude sacar es que los adultos mayores con la tasa menor de supervivencia(31%), Y los Jóvenes (35%) Me dieron a entender que claramente, El enfoque estaba en que los niños fueran quienes debían sobrevivir por encima del resto, Mientras que los grupos de mayor edad tenían menos prioridad en la evacuación
... A44: Asimismo las diferencias en las tarifas reflejan una marcada desiguladad socioeconomica entre clases, l ocual se vincula con las distintas tasas de supervivencia observadas. En conjunto, los datos evidencian que factores estructurales y sociales tuvieron peso determinante en los resultados.

Sheet DATASET_ORIGINAL
A3: PassengerId,Survived,Pclass,Name,Sex,Age,SibSp,Parch,Ticket,Fare,Cabin,Embarked
A4: 1,0,3,"Braund, Mr. Owen Harris",male,22,1,0,A/5 21171,7.25,,S
A5: 2,1,1,"Cumings, Mrs. John Bradley (Florence Briggs Thayer)",female,38,1,0,PC 17599,71.2833,C85,C
A6: 3,1,3,"Heikkinen, Miss. Laina",female,26,0,0,STON/O2. 3101282,7.925,,S
A7: 4,1,1,"Futrelle, Mrs. Jacques Heath (Lily May Peel)",female,35,1,0,113803,53.1,C123,S
A8: 5,0,3,"Allen, Mr. William Henry",male,35,0,0,373450,8.05,,S
A9: 6,0,3,"Moran, Mr. James",male,,0,0,330877,8.4583,,Q
A10: 7,0,1,"McCarthy, Mr. Timothy J",male,54,0,0,17463,51.8625,E46,S
A11: 8,0,3,"Palsson, Master. Gosta Leonard",male,2,3,1,349909,21.075,,S
A12: 9,1,3,"Johnson, Mrs. Oscar W (Elisabeth Vilhelmina Berg)",female,27,0,2,347742,11.1333,,S
A13: 10,1,2,"Nasser, Mrs. Nicholas (Adele Achem)",female,14,1,0,237736,30.0708,,C
A14: 11,1,3,"Sandstrom, Miss. Marguerite Rut",female,4,1,1,PP 9549,16.7,G6,S
... A894: 891,0,3,"Dooley, Mr. Patrick",male,32,0,0,370376,7.75,,Q

Sheet DATASET
A3: PassengerId. | B3: Survived | C3: Pclass | D3: Name . | E3: Sex . | F3: Age Clean | G3: Age Correción 2 | H3: Age Correción. | I3: Age | J3: SibSp | K3: Parch | L3: Ticket | M3: Fare correción | N3: Fare | O3: Cabin Correción | P3: Cabin | Q3: Embarked
A4: 546 | B4: 0 | C4: 1 | D4: Nicholson, Mr. Arthur Ernest | E4: male | F4: =ROUNDUP(Titanic_DATASET[[#This Row],[Age Correción 2]],0) -> 64 | G4: =VALUE(SUBSTITUTE(Titanic_DATASET[[#This Row],[Age Correción.]],".",",")) -> 64 | H4: 64 | I4: 64 | J4: 0 | K4: 0 | L4: 693 | M4: =VALUE(SUBSTITUTE(N4,".",",")) -> 26 | N4: 26 | O4: =IF(ISBLANK(P4),"Desconocido",P4) -> Desconocido | Q4: S
A5: 873 | B5: 0 | C5: 1 | D5: Carlsson, Mr. Frans Olof | E5: male | F5: =ROUNDUP(Titanic_DATASET[[#This Row],[Age Correción 2]],0) -> 33 | G5: =VALUE(SUBSTITUTE(Titanic_DATASET[[#This Row],[Age Correción.]],".",",")) -> 33 | H5: 33 | I5: 33 | J5: 0 | K5: 0 | L5: 695 | M5: =VALUE(SUBSTITUTE(N5,".",",")) -> 5 | N5: 5 | O5: =IF(ISBLANK(P5),"Desconocido",P5) -> B51 B53 B55 | P5: B51 B53 B55 | Q5: S
A6: 75 | B6: 1 | C6: 3 | D6: Bing, Mr. Lee | E6: male | F6: =ROUNDUP(Titanic_DATASET[[#This Row],[Age Correción 2]],0) -> 32 | G6: =VALUE(SUBSTITUTE(Titanic_DATASET[[#This Row],[Age Correción.]],".",",")) -> 32 | H6: 32 | I6: 32 | J6: 0 | K6: 0 | L6: 1601 | M6: =VALUE(SUBSTITUTE(N6,".",",")) -> 564958 | N6: 564958 | O6: =IF(ISBLANK(P6),"Desconocido",P6) -> Desconocido | Q6: S
A7: 170 | B7: 0 | C7: 3 | D7: Ling, Mr. Lee | E7: male | F7: =ROUNDUP(Titanic_DATASET[[#This Row],[Age Correción 2]],0) -> 28 | G7: =VALUE(SUBSTITUTE(Titanic_DATASET[[#This Row],[Age Correción.]],".",",")) -> 28 | H7: 28 | I7: 28 | J7: 0 | K7: 0 | L7: 1601 | M7: =VALUE(SUBSTITUTE(N7,".",",")) -> 564958 | N7: 564958 | O7: =IF(ISBLANK(P7),"Desconocido",P7) -> Desconocido | Q7: S
A8: 510 | B8: 1 | C8: 3 | D8: Lang, Mr. Fang | E8: male | F8: =ROUNDUP(Titanic_DATASET[[#This Row],[Age Correción 2]],0) -> 26 | G8: =VALUE(SUBSTITUTE(Titanic_DATASET[[#This Row],[Age Correción.]],".",",")) -> 26 | H8: 26 | I8: 26 | J8: 0 | K8: 0 | L8: 1601 | M8: =VALUE(SUBSTITUTE(N8,".",",")) -> 564958 | N8: 564958 | O8: =IF(ISBLANK(P8),"Desconocido",P8) -> Desconocido | Q8: S
A9: 644 | B9: 1 | C9: 3 | D9: Foo, Mr. Choong | E9: male | F9: =ROUNDUP(Titanic_DATASET[[#This Row],[Age Correción 2]],0) -> 42 | G9: =VALUE(SUBSTITUTE(Titanic_DATASET[[#This Row],[Age Correción.]],".",",")) -> 42 | H9: 42 | J9: 0 | K9: 0 | L9: 1601 | M9: =VALUE(SUBSTITUTE(N9,".",",")) -> 564958 | N9: 564958 | O9: =IF(ISBLANK(P9),"Desconocido",P9) -> Desconocido | Q9: S
A10: 693 | B10: 1 | C10: 3 | D10: Lam, Mr. Ali | E10: male | F10: =ROUNDUP(Titanic_DATASET[[#This Row],[Age Correción 2]],0) -> 58 | G10: =VALUE(SUBSTITUTE(Titanic_DATASET[[#This Row],[Age Correción.]],".",",")) -> 58 | H10: 58 | J10: 0 | K10: 0 | L10: 1601 | M10: =VALUE(SUBSTITUTE(N10,".",",")) -> 564958 | N10: 564958 | O10: =IF(ISBLANK(P10),"Desconocido",P10) -> Desconocido | Q10: S
A11: 827 | B11: 0 | C11: 3 | D11: Lam, Mr. Len | E11: male | F11: =ROUNDUP(Titanic_DATASET[[#This Row],[Age Correción 2]],0) -> 57 | G11: =VALUE(SUBSTITUTE(Titanic_DATASET[[#This Row],[Age Correción.]],".",",")) -> 57 | H11: 57 | J11: 0 | K11: 0 | L11: 1601 | M11: =VALUE(SUBSTITUTE(N11,".",",")) -> 564958 | N11: 564958 | O11: =IF(ISBLANK(P11),"Desconocido",P11) -> Desconocido | Q11: S
A12: 839 | B12: 1 | C12: 3 | D12: Chip, Mr. Chang | E12: male | F12: =ROUNDUP(Titanic_DATASET[[#This Row],[Age Correción 2]],0) -> 32 | G12: =VALUE(SUBSTITUTE(Titanic_DATASET[[#This Row],[Age Correción.]],".",",")) -> 32 | H12: 32 | I12: 32 | J12: 0 | K12: 0 | L12: 1601 | M12: =VALUE(SUBSTITUTE(N12,".",",")) -> 564958 | N12: 564958 | O12: =IF(ISBLANK(P12),"Desconocido",P12) -> Desconocido | Q12: S
A13: 427 | B13: 1 | C13: 2 | D13: Clarke, Mrs. Charles V (Ada Maria Winfield) | E13: female | F13: =ROUNDUP(Titanic_DATASET[[#This Row],[Age Correción 2]],0) -> 28 | G13: =VALUE(SUBSTITUTE(Titanic_DATASET[[#This Row],[Age Correción.]],".",",")) -> 28 | H13: 28 | I13: 28 | J13: 1 | K13: 0 | L13: 2003 | M13: =VALUE(SUBSTITUTE(N13,".",",")) -> 26 | N13: 26 | O13: =IF(ISBLANK(P13),"Desconocido",P13) -> Desconocido | Q13: S
A14: 835 | B14: 0 | C14: 3 | D14: Allum, Mr. Owen George | E14: male | F14: =ROUNDUP(Titanic_DATASET[[#This Row],[Age Correción 2]],0) -> 18 | G14: =VALUE(SUBSTITUTE(Titanic_DATASET[[#This Row],[Age Correción.]],".",",")) -> 18 | H14: 18 | I14: 18 | J14: 0 | K14: 0 | L14: 2223 | M14: =VALUE(SUBSTITUTE(N14,".",",")) -> 8.3 | N14: 8.3 | O14: =IF(ISBLANK(P14),"Desconocido",P14) -> Desconocido | Q14: S
A15: 554 | B15: 1 | C15: 3 | D15: Leeni, Mr. Fahim ("Philip Zenni") | E15: male | F15: =ROUNDUP(Titanic_DATASET[[#This Row],[Age Correción 2]],0) -> 22 | G15: =VALUE(SUBSTITUTE(Titanic_DATASET[[#This Row],[Age Correción.]],".",",")) -> 22 | H15: 22 | I15: 22 | J15: 0 | K15: 0 | L15: 2620 | M15: =VALUE(SUBSTITUTE(N15,".",",")) -> 7225 | N15: 7225 | O15: =IF(ISBLANK(P15),"Desconocido",P15) -> Desconocido | Q15: C
A16: 662 | B16: 0 | C16: 3 | D16: Badt, Mr. Mohamed | E16: male | F16: =ROUNDUP(Titanic_DATASET[[#This Row],[Age Correción 2]],0) -> 40 | G16: =VALUE(SUBSTITUTE(Titanic_DATASET[[#This Row],[Age Correción.]],".",",")) -> 40 | H16: 40 | I16: 40 | J16: 0 | K16: 0 | L16: 2623 | M16: =VALUE(SUBSTITUTE(N16,".",",")) -> 7225 | N16: 7225 | O16: =IF(ISBLANK(P16),"Desconocido",P16) -> Desconocido | Q16: C
A17: 523 | B17: 0 | C17: 3 | D17: Lahoud, Mr. Sarkis | E17: male | F17: =ROUNDUP(Titanic_DATASET[[#This Row],[Age Correción 2]],0) -> 59 | G17: =VALUE(SUBSTITUTE(Titanic_DATASET[[#This Row],[Age Correción.]],".",",")) -> 59 | H17: 59 | J17: 0 | K17: 0 | L17: 2624 | M17: =VALUE(SUBSTITUTE(N17,".",",")) -> 7225 | N17: 7225 | O17: =IF(ISBLANK(P17),"Desconocido",P17) -> Desconocido | Q17: C
A18: 804 | B18: 1 | C18: 3 | D18: Thomas, Master. Assad Alexander | E18: male | F18: =ROUNDUP(Titanic_DATASET[[#This Row],[Age Correción 2]],0) -> 1 | G18: =VALUE(SUBSTITUTE(Titanic_DATASET[[#This Row],[Age Correción.]],".",",")) -> 0.42 | H18: 0.42 | I18: 0.42 | J18: 0 | K18: 1 | L18: 2625 | M18: =VALUE(SUBSTITUTE(N18,".",",")) -> 85167 | N18: 85167 | O18: =IF(ISBLANK(P18),"Desconocido",P18) -> Desconocido | Q18: C
A19: 368 | B19: 1 | C19: 3 | D19: Moussa, Mrs. (Mantoura Boulos) | E19: female | F19: =ROUNDUP(Titanic_DATASET[[#This Row],[Age Correción 2]],0) -> 45 | G19: =VALUE(SUBSTITUTE(Titanic_DATASET[[#This Row],[Age Correción.]],".",",")) -> 45 | H19: 45 | J19: 0 | K19: 0 | L19: 2626 | M19: =VALUE(SUBSTITUTE(N19,".",",")) -> 72292 | N19: 72292 | O19: =IF(ISBLANK(P19),"Desconocido",P19) -> Desconocido | Q19: C
A20: 115 | B20: 0 | C20: 3 | D20: Attalah, Miss. Malake | E20: female | F20: =ROUNDUP(Titanic_DATASET[[#This Row],[Age Correción 2]],0) -> 17 | G20: =VALUE(SUBSTITUTE(Titanic_DATASET[[#This Row],[Age Correción.]],".",",")) -> 17 | H20: 17 | I20: 17 | J20: 0 | K20: 0 | L20: 2627 | M20: =VALUE(SUBSTITUTE(N20,".",",")) -> 144583 | N20: 144583 | O20: =IF(ISBLANK(P20),"Desconocido",P20) -> Desconocido | Q20: C
A21: 496 | B21: 0 | C21: 3 | D21: Yousseff, Mr. Gerious | E21: male | F21: =ROUNDUP(Titanic_DATASET[[#This Row],[Age Correción 2]],0) -> 80 | G21: =VALUE(SUBSTITUTE(Titanic_DATASET[[#This Row],[Age Correción.]],".",",")) -> 80 | H21: 80 | J21: 0 | K21: 0 | L21: 2627 | M21: =VALUE(SUBSTITUTE(N21,".",",")) -> 144583 | N21: 144583 | O21: =IF(ISBLANK(P21),"Desconocido",P21) -> Desconocido | Q21: C
A22: 204 | B22: 0 | C22: 3 | D22: Youseff, Mr. Gerious | E22: male | F22: =ROUNDUP(Titanic_DATASET[[#This Row],[Age Correción 2]],0) -> 46 | G22: =VALUE(SUBSTITUTE(Titanic_DATASET[[#This Row],[Age Correción.]],".",",")) -> 45.5 | H22: 45.5 | I22: 45.5 | J22: 0 | K22: 0 | L22: 2628 | M22: =VALUE(SUBSTITUTE(N22,".",",")) -> 7225 | N22: 7225 | O22: =IF(ISBLANK(P22),"Desconocido",P22) -> Desconocido | Q22: C
A23: 860 | B23: 0 | C23: 3 | D23: Razi, Mr. Raihed | E23: male | F23: =ROUNDUP(Titanic_DATASET[[#This Row],[Age Correción 2]],0) -> 33 | G23: =VALUE(SUBSTITUTE(Titanic_DATASET[[#This Row],[Age Correción.]],".",",")) -> 33 | H23: 33 | J23: 0 | K23: 0 | L23: 2629 | M23: =VALUE(SUBSTITUTE(N23,".",",")) -> 72292 | N23: 72292 | O23: =IF(ISBLANK(P23),"Desconocido",P23) -> Desconocido | Q23: C
A24: 27 | B24: 0 | C24: 3 | D24: Emir, Mr. Farred Chehab | E24: male | F24: =ROUNDUP(Titanic_DATASET[[#This Row],[Age Correción 2]],0) -> 75 | G24: =VALUE(SUBSTITUTE(Titanic_DATASET[[#This Row],[Age Correción.]],".",",")) -> 75 | H24: 75 | J24: 0 | K24: 0 | L24: 2631 | M24: =VALUE(SUBSTITUTE(N24,".",",")) -> 7225 | N24: 7225 | O24: =IF(ISBLANK(P24),"Desconocido",P24) -> Desconocido | Q24: C
A25: 532 | B25: 0 | C25: 3 | D25: Toufik, Mr. Nakli | E25: male | F25: =ROUNDUP(Titanic_DATASET[[#This Row],[Age Correción 2]],0) -> 52 | G25: =VALUE(SUBSTITUTE(Titanic_DATASET[[#This Row],[Age Correción.]],".",",")) -> 52 | H25: 52 | J25: 0 | K25: 0 | L25: 2641 | M25: =VALUE(SUBSTITUTE(N25,".",",")) -> 72292 | N25: 72292 | O25: =IF(ISBLANK(P25),"Desconocido",P25) -> Desconocido | Q25: C
A26: 355 | B26: 0 | C26: 3 | D26: Yousif, Mr. Wazli | E26: male | F26: =ROUNDUP(Titanic_DATASET[[#This Row],[Age Correción 2]],0) -> 4 | G26: =VALUE(SUBSTITUTE(Titanic_DATASET[[#This Row],[Age Correción.]],".",",")) -> 4 | H26: 4 | J26: 0 | K26: 0 | L26: 2647 | M26: =VALUE(SUBSTITUTE(N26,".",",")) -> 7225 | N26: 7225 | O26: =IF(ISBLANK(P26),"Desconocido",P26) -> Desconocido | Q26: C
A27: 379 | B27: 0 | C27: 3 | D27: Betros, Mr. Tannous | E27: male | F27: =ROUNDUP(Titanic_DATASET[[#This Row],[Age Correción 2]],0) -> 20 | G27: =VALUE(SUBSTITUTE(Titanic_DATASET[[#This Row],[Age Correción.]],".",",")) -> 20 | H27: 20 | I27: 20 | J27: 0 | K27: 0 | L27: 2648 | M27: =VALUE(SUBSTITUTE(N27,".",",")) -> 40125 | N27: 40125 | O27: =IF(ISBLANK(P27),"Desconocido",P27) -> Desconocido | Q27: C
A28: 20 | B28: 1 | C28: 3 | D28: Masselmani, Mrs. Fatima | E28: female | F28: =ROUNDUP(Titanic_DATASET[[#This Row],[Age Correción 2]],0) -> 38 | G28: =VALUE(SUBSTITUTE(Titanic_DATASET[[#This Row],[Age Correción.]],".",",")) -> 38 | H28: 38 | J28: 0 | K28: 0 | L28: 2649 | M28: =VALUE(SUBSTITUTE(N28,".",",")) -> 7225 | N28: 7225 | O28: =IF(ISBLANK(P28),"Desconocido",P28) -> Desconocido | Q28: C
A29: 256 | B29: 1 | C29: 3 | D29: Touma, Mrs. Darwis (Hanne Youssef Razi) | E29: female | F29: =ROUNDUP(Titanic_DATASET[[#This Row],[Age Correción 2]],0) -> 29 | G29: =VALUE(SUBSTITUTE(Titanic_DATASET[[#This Row],[Age Correción.]],".",",")) -> 29 | H29: 29 | I29: 29 | J29: 0 | K29: 2 | L29: 2650 | M29: =VALUE(SUBSTITUTE(N29,".",",")) -> 152458 | N29: 152458 | O29: =IF(ISBLANK(P29),"Desconocido",P29) -> Desconocido | Q29: C
A30: 40 | B30: 1 | C30: 3 | D30: Nicola-Yarred, Miss. Jamila | E30: female | F30: =ROUNDUP(Titanic_DATASET[[#This Row],[Age Correción 2]],0) -> 14 | G30: =VALUE(SUBSTITUTE(Titanic_DATASET[[#This Row],[Age Correción.]],".",",")) -> 14 | H30: 14 | I30: 14 | J30: 1 | K30: 0 | L30: 2651 | M30: =VALUE(SUBSTITUTE(N30,".",",")) -> 112417 | N30: 112417 | O30: =IF(ISBLANK(P30),"Desconocido",P30) -> Desconocido | Q30: C
A31: 126 | B31: 1 | C31: 3 | D31: Nicola-Yarred, Master. Elias | E31: male | F31: =ROUNDUP(Titanic_DATASET[[#This Row],[Age Correción 2]],0) -> 12 | G31: =VALUE(SUBSTITUTE(Titanic_DATASET[[#This Row],[Age Correción.]],".",",")) -> 12 | H31: 12 | I31: 12 | J31: 1 | K31: 0 | L31: 2651 | M31: =VALUE(SUBSTITUTE(N31,".",",")) -> 112417 | N31: 112417 | O31: =IF(ISBLANK(P31),"Desconocido",P31) -> Desconocido | Q31: C
A32: 382 | B32: 1 | C32: 3 | D32: Nakid, Miss. Maria ("Mary") | E32: female | F32: =ROUNDUP(Titanic_DATASET[[#This Row],[Age Correción 2]],0) -> 1 | G32: =VALUE(SUBSTITUTE(Titanic_DATASET[[#This Row],[Age Correción.]],".",",")) -> 1 | H32: 1 | I32: 1 | J32: 0 | K32: 2 | L32: 2653 | M32: =VALUE(SUBSTITUTE(N32,".",",")) -> 157417 | N32: 157417 | O32: =IF(ISBLANK(P32),"Desconocido",P32) -> Desconocido | Q32: C
A33: 623 | B33: 1 | C33: 3 | D33: Nakid, Mr. Sahid | E33: male | F33: =ROUNDUP(Titanic_DATASET[[#This Row],[Age Correción 2]],0) -> 20 | G33: =VALUE(SUBSTITUTE(Titanic_DATASET[[#This Row],[Age Correción.]],".",",")) -> 20 | H33: 20 | I33: 20 | J33: 1 | K33: 1 | L33: 2653 | M33: =VALUE(SUBSTITUTE(N33,".",",")) -> 157417 | N33: 157417 | O33: =IF(ISBLANK(P33),"Desconocido",P33) -> Desconocido | Q33: C
A34: 621 | B34: 0 | C34: 3 | D34: Yasbeck, Mr. Antoni | E34: male | F34: =ROUNDUP(Titanic_DATASET[[#This Row],[Age Correción 2]],0) -> 27 | G34: =VALUE(SUBSTITUTE(Titanic_DATASET[[#This Row],[Age Correción.]],".",",")) -> 27 | H34: 27 | I34: 27 | J34: 1 | K34: 0 | L34: 2659 | M34: =VALUE(SUBSTITUTE(N34,".",",")) -> 144542 | N34: 144542 | O34: =IF(ISBLANK(P34),"Desconocido",P34) -> Desconocido | Q34: C
A35: 831 | B35: 1 | C35: 3 | D35: Yasbeck, Mrs. Antoni (Selini Alexander) | E35: female | F35: =ROUNDUP(Titanic_DATASET[[#This Row],[Age Correción 2]],0) -> 15 | G35: =VALUE(SUBSTITUTE(Titanic_DATASET[[#This Row],[Age Correción.]],".",",")) -> 15 | H35: 15 | I35: 15 | J35: 1 | K35: 0 | L35: 2659 | M35: =VALUE(SUBSTITUTE(N35,".",",")) -> 144542 | N35: 144542 | O35: =IF(ISBLANK(P35),"Desconocido",P35) -> Desconocido | Q35: C
A36: 66 | B36: 1 | C36: 3 | D36: Moubarek, Master. Gerios | E36: male | F36: =ROUNDUP(Titanic_DATASET[[#This Row],[Age Correción 2]],0) -> 38 | G36: =VALUE(SUBSTITUTE(Titanic_DATASET[[#This Row],[Age Correción.]],".",",")) -> 38 | H36: 38 | J36: 1 | K36: 1 | L36: 2661 | M36: =VALUE(SUBSTITUTE(N36,".",",")) -> 152458 | N36: 152458 | O36: =IF(ISBLANK(P36),"Desconocido",P36) -> Desconocido | Q36: C
A37: 710 | B37: 1 | C37: 3 | D37: Moubarek, Master. Halim Gonios ("William George") | E37: male | F37: =ROUNDUP(Titanic_DATASET[[#This Row],[Age Correción 2]],0) -> 36 | G37: =VALUE(SUBSTITUTE(Titanic_DATASET[[#This Row],[Age Correción.]],".",",")) -> 36 | H37: 36 | J37: 1 | K37: 1 | L37: 2661 | M37: =VALUE(SUBSTITUTE(N37,".",",")) -> 152458 | N37: 152458 | O37: =IF(ISBLANK(P37),"Desconocido",P37) -> Desconocido | Q37: C
A38: 49 | B38: 0 | C38: 3 | D38: Samaan, Mr. Youssef | E38: male | F38: =ROUNDUP(Titanic_DATASET[[#This Row],[Age Correción 2]],0) -> 78 | G38: =VALUE(SUBSTITUTE(Titanic_DATASET[[#This Row],[Age Correción.]],".",",")) -> 78 | H38: 78 | J38: 2 | K38: 0 | L38: 2662 | M38: =VALUE(SUBSTITUTE(N38,".",",")) -> 216792 | N38: 216792 | O38: =IF(ISBLANK(P38),"Desconocido",P38) -> Desconocido | Q38: C
A39: 763 | B39: 1 | C39: 3 | D39: Barah, Mr. Hanna Assi | E39: male | F39: =ROUNDUP(Titanic_DATASET[[#This Row],[Age Correción 2]],0) -> 20 | G39: =VALUE(SUBSTITUTE(Titanic_DATASET[[#This Row],[Age Correción.]],".",",")) -> 20 | H39: 20 | I39: 20 | J39: 0 | K39: 0 | L39: 2663 | M39: =VALUE(SUBSTITUTE(N39,".",",")) -> 72292 | N39: 72292 | O39: =IF(ISBLANK(P39),"Desconocido",P39) -> Desconocido | Q39: C
A40: 599 | B40: 0 | C40: 3 | D40: Boulos, Mr. Hanna | E40: male | F40: =ROUNDUP(Titanic_DATASET[[#This Row],[Age Correción 2]],0) -> 5 | G40: =VALUE(SUBSTITUTE(Titanic_DATASET[[#This Row],[Age Correción.]],".",",")) -> 5 | H40: 5 | J40: 0 | K40: 0 | L40: 2664 | M40: =VALUE(SUBSTITUTE(N40,".",",")) -> 7225 | N40: 7225 | O40: =IF(ISBLANK(P40),"Desconocido",P40) -> Desconocido | Q40: C
A41: 112 | B41: 0 | C41: 3 | D41: Zabour, Miss. Hileni | E41: female | F41: =ROUNDUP(Titanic_DATASET[[#This Row],[Age Correción 2]],0) -> 15 | G41: =VALUE(SUBSTITUTE(Titanic_DATASET[[#This Row],[Age Correción.]],".",",")) -> 14.5 | H41: 14.5 | I41: 14.5 | J41: 1 | K41: 0 | L41: 2665 | M41: =VALUE(SUBSTITUTE(N41,".",",")) -> 144542 | N41: 144542 | O41: =IF(ISBLANK(P41),"Desconocido",P41) -> Desconocido | Q41: C
A42: 241 | B42: 0 | C42: 3 | D42: Zabour, Miss. Thamine | E42: female | F42: =ROUNDUP(Titanic_DATASET[[#This Row],[Age Correción 2]],0) -> 29 | G42: =VALUE(SUBSTITUTE(Titanic_DATASET[[#This Row],[Age Correción.]],".",",")) -> 29 | H42: 29 | J42: 1 | K42: 0 | L42: 2665 | M42: =VALUE(SUBSTITUTE(N42,".",",")) -> 144542 | N42: 144542 | O42: =IF(ISBLANK(P42),"Desconocido",P42) -> Desconocido | Q42: C
...

Sheet DATASET_CLEAN
A3: Nombre | B3: Sexo | C3: ID_Pasajero | D3: Edad | E3: Padres_Hijos | F3: Hermanos/Cónyuge | G3: Clase_Del_Pasaje | H3: Sobreviviente | I3: Ticket | J3: Tarifa | K3: Cabina | L3: Embarque | M3: Rango Etario
A4: Braund, Mr. Owen Harris | B4: male | C4: 1 | D4: 64 | E4: 0 | F4: 1 | G4: 3 | H4: 0 | I4: 693 | J4: 7.25 | K4: Desconocido | L4: S | M4: {=_xlfn.IFS(INFO_Pasajeros[[#This Row],[Edad]]<=13,"Niños",INFO_Pasajeros[[#This Row],[Edad]]<=18,"Jóvenes",INFO_Pasajeros[[#This Row],[Edad]]<=50,"Adultos",INFO_Pasajeros[[#This Row],[Edad]]>=51,"Adultos Mayores")} -> Adultos Mayores
A5: Cumings, Mrs. John Bradley (Florence Briggs Thayer) | B5: female | C5: 2 | D5: 33 | E5: 0 | F5: 1 | G5: 1 | H5: 1 | I5: 695 | J5: 712.833 | K5: B51 B53 B55 | L5: S | M5: {=_xlfn.IFS(INFO_Pasajeros[[#This Row],[Edad]]<=13,"Niños",INFO_Pasajeros[[#This Row],[Edad]]<=18,"Jóvenes",INFO_Pasajeros[[#This Row],[Edad]]<=50,"Adultos",INFO_Pasajeros[[#This Row],[Edad]]>=51,"Adultos Mayores")} -> Adultos
A6: Heikkinen, Miss. Laina | B6: female | C6: 3 | D6: 32 | E6: 0 | F6: 0 | G6: 3 | H6: 1 | I6: 1601 | J6: 7.925 | K6: Desconocido | L6: S | M6: {=_xlfn.IFS(INFO_Pasajeros[[#This Row],[Edad]]<=13,"Niños",INFO_Pasajeros[[#This Row],[Edad]]<=18,"Jóvenes",INFO_Pasajeros[[#This Row],[Edad]]<=50,"Adultos",INFO_Pasajeros[[#This Row],[Edad]]>=51,"Adultos Mayores")} -> Adultos
A7: Futrelle, Mrs. Jacques Heath (Lily May Peel) | B7: female | C7: 4 | D7: 28 | E7: 0 | F7: 1 | G7: 1 | H7: 1 | I7: 1601 | J7: 53.1 | K7: Desconocido | L7: S | M7: {=_xlfn.IFS(INFO_Pasajeros[[#This Row],[Edad]]<=13,"Niños",INFO_Pasajeros[[#This Row],[Edad]]<=18,"Jóvenes",INFO_Pasajeros[[#This Row],[Edad]]<=50,"Adultos",INFO_Pasajeros[[#This Row],[Edad]]>=51,"Adultos Mayores")} -> Adultos
A8: Allen, Mr. William Henry | B8: male | C8: 5 | D8: 26 | E8: 0 | F8: 0 | G8: 3 | H8: 0 | I8: 1601 | J8: 8.05 | K8: Desconocido | L8: S | M8: {=_xlfn.IFS(INFO_Pasajeros[[#This Row],[Edad]]<=13,"Niños",INFO_Pasajeros[[#This Row],[Edad]]<=18,"Jóvenes",INFO_Pasajeros[[#This Row],[Edad]]<=50,"Adultos",INFO_Pasajeros[[#This Row],[Edad]]>=51,"Adultos Mayores")} -> Adultos
A9: Moran, Mr. James | B9: male | C9: 6 | D9: 42 | E9: 0 | F9: 0 | G9: 3 | H9: 0 | I9: 1601 | J9: 84.583 | K9: Desconocido | L9: S | M9: {=_xlfn.IFS(INFO_Pasajeros[[#This Row],[Edad]]<=13,"Niños",INFO_Pasajeros[[#This Row],[Edad]]<=18,"Jóvenes",INFO_Pasajeros[[#This Row],[Edad]]<=50,"Adultos",INFO_Pasajeros[[#This Row],[Edad]]>=51,"Adultos Mayores")} -> Adultos
A10: McCarthy, Mr. Timothy J | B10: male | C10: 7 | D10: 58 | E10: 0 | F10: 0 | G10: 1 | H10: 0 | I10: 1601 | J10: 518.625 | K10: Desconocido | L10: S | M10: {=_xlfn.IFS(INFO_Pasajeros[[#This Row],[Edad]]<=13,"Niños",INFO_Pasajeros[[#This Row],[Edad]]<=18,"Jóvenes",INFO_Pasajeros[[#This Row],[Edad]]<=50,"Adultos",INFO_Pasajeros[[#This Row],[Edad]]>=51,"Adultos Mayores")} -> Adultos Mayores
A11: Palsson, Master. Gosta Leonard | B11: male | C11: 8 | D11: 57 | E11: 1 | F11: 3 | G11: 3 | H11: 0 | I11: 1601 | J11: 21.075 | K11: Desconocido | L11: S | M11: {=_xlfn.IFS(INFO_Pasajeros[[#This Row],[Edad]]<=13,"Niños",INFO_Pasajeros[[#This Row],[Edad]]<=18,"Jóvenes",INFO_Pasajeros[[#This Row],[Edad]]<=50,"Adultos",INFO_Pasajeros[[#This Row],[Edad]]>=51,"Adultos Mayores")} -> Adultos Mayores
A12: Johnson, Mrs. Oscar W (Elisabeth Vilhelmina Berg) | B12: female | C12: 9 | D12: 32 | E12: 2 | F12: 0 | G12: 3 | H12: 1 | I12: 1601 | J12: 111.333 | K12: Desconocido | L12: S | M12: {=_xlfn.IFS(INFO_Pasajeros[[#This Row],[Edad]]<=13,"Niños",INFO_Pasajeros[[#This Row],[Edad]]<=18,"Jóvenes",INFO_Pasajeros[[#This Row],[Edad]]<=50,"Adultos",INFO_Pasajeros[[#This Row],[Edad]]>=51,"Adultos Mayores")} -> Adultos
A13: Nasser, Mrs. Nicholas (Adele Achem) | B13: female | C13: 10 | D13: 28 | E13: 0 | F13: 1 | G13: 2 | H13: 1 | I13: 2003 | J13: 300.708 | K13: Desconocido | L13: S | M13: {=_xlfn.IFS(INFO_Pasajeros[[#This Row],[Edad]]<=13,"Niños",INFO_Pasajeros[[#This Row],[Edad]]<=18,"Jóvenes",INFO_Pasajeros[[#This Row],[Edad]]<=50,"Adultos",INFO_Pasajeros[[#This Row],[Edad]]>=51,"Adultos Mayores")} -> Adultos
A14: Sandstrom, Miss. Marguerite Rut | B14: female | C14: 11 | D14: 18 | E14: 1 | F14: 1 | G14: 3 | H14: 1 | I14: 2223 | J14: 16.7 | K14: Desconocido | L14: S | M14: {=_xlfn.IFS(INFO_Pasajeros[[#This Row],[Edad]]<=13,"Niños",INFO_Pasajeros[[#This Row],[Edad]]<=18,"Jóvenes",INFO_Pasajeros[[#This Row],[Edad]]<=50,"Adultos",INFO_Pasajeros[[#This Row],[Edad]]>=51,"Adultos Mayores")} -> Jóvenes
A15: Bonnell, Miss. Elizabeth | B15: female | C15: 12 | D15: 22 | E15: 0 | F15: 0 | G15: 1 | H15: 1 | I15: 2620 | J15: 26.55 | K15: Desconocido | L15: C | M15: {=_xlfn.IFS(INFO_Pasajeros[[#This Row],[Edad]]<=13,"Niños",INFO_Pasajeros[[#This Row],[Edad]]<=18,"Jóvenes",INFO_Pasajeros[[#This Row],[Edad]]<=50,"Adultos",INFO_Pasajeros[[#This Row],[Edad]]>=51,"Adultos Mayores")} -> Adultos
... A664: Frauenthal, Dr. Henry William | B664: male | C664: 661 | D664: 2 | E664: 0 | F664: 2 | G664: 1 | H664: 1 | I664: 3101298 | J664: 133.65 | K664: Desconocido | L664: S | M664: {=_xlfn.IFS(INFO_Pasajeros[[#This Row],[Edad]]<=13,"Niños",INFO_Pasajeros[[#This Row],[Edad]]<=18,"Jóvenes",INFO_Pasajeros[[#This Row],[Edad]]<=50,"Adultos",INFO_Pasajeros[[#This Row],[Edad]]>=51,"Adultos Mayores")} -> Niños
A665: Badt, Mr. Mohamed | B665: male | C665: 662 | D665: 21 | E665: 0 | F665: 0 | G665: 3 | H665: 0 | I665: A./5. 2152 | J665: 7.225 | K665: Desconocido | L665: S | M665: {=_xlfn.IFS(INFO_Pasajeros[[#This Row],[Edad]]<=13,"Niños",INFO_Pasajeros[[#This Row],[Edad]]<=18,"Jóvenes",INFO_Pasajeros[[#This Row],[Edad]]<=50,"Adultos",INFO_Pasajeros[[#This Row],[Edad]]>=51,"Adultos Mayores")} -> Adultos
A666: Colley, Mr. Edward Pomeroy | B666: male | C666: 663 | D666: 56 | E666: 0 | F666: 0 | G666: 1 | H666: 0 | I666: A./5. 3235 | J666: 255.875 | K666: Desconocido | L666: S | M666: {=_xlfn.IFS(INFO_Pasajeros[[#This Row],[Edad]]<=13,"Niños",INFO_Pasajeros[[#This Row],[Edad]]<=18,"Jóvenes",INFO_Pasajeros[[#This Row],[Edad]]<=50,"Adultos",INFO_Pasajeros[[#This Row],[Edad]]>=51,"Adultos Mayores")} -> Adultos Mayores
A667: Coleff, Mr. Peju | B667: male | C667: 664 | D667: 56 | E667: 0 | F667: 0 | G667: 3 | H667: 0 | I667: A.5. 11206 | J667: 74.958 | K667: Desconocido | L667: S | M667: {=_xlfn.IFS(INFO_Pasajeros[[#This Row],[Edad]]<=13,"Niños",INFO_Pasajeros[[#This Row],[Edad]]<=18,"Jóvenes",INFO_Pasajeros[[#This Row],[Edad]]<=50,"Adultos",INFO_Pasajeros[[#This Row],[Edad]]>=51,"Adultos Mayores")} -> Adultos Mayores
A668: Lindqvist, Mr. Eino William | B668: male | C668: 665 | D668: 30 | E668: 0 | F668: 1 | G668: 3 | H668: 1 | I668: A.5. 18509 | J668: 7.925 | K668: Desconocido | L668: S | M668: {=_xlfn.IFS(INFO_Pasajeros[[#This Row],[Edad]]<=13,"Niños",INFO_Pasajeros[[#This Row],[Edad]]<=18,"Jóvenes",INFO_Pasajeros[[#This Row],[Edad]]<=50,"Adultos",INFO_Pasajeros[[#This Row],[Edad]]>=51,"Adultos Mayores")} -> Adultos
A669: Hickman, Mr. Lewis | B669: male | C669: 666 | D669: 21 | E669: 0 | F669: 2 | G669: 2 | H669: 0 | I669: A/4 45380 | J669: 73.5 | K669: Desconocido | L669: S | M669: {=_xlfn.IFS(INFO_Pasajeros[[#This Row],[Edad]]<=13,"Niños",INFO_Pasajeros[[#This Row],[Edad]]<=18,"Jóvenes",INFO_Pasajeros[[#This Row],[Edad]]<=50,"Adultos",INFO_Pasajeros[[#This Row],[Edad]]>=51,"Adultos Mayores")} -> Adultos
A670: Butler, Mr. Reginald Fenton | B670: male | C670: 667 | D670: 24 | E670: 0 | F670: 0 | G670: 2 | H670: 0 | I670: A/4 48871 | J670: 13 | K670: Desconocido | L670: S | M670: {=_xlfn.IFS(INFO_Pasajeros[[#This Row],[Edad]]<=13,"Niños",INFO_Pasajeros[[#This Row],[Edad]]<=18,"Jóvenes",INFO_Pasajeros[[#This Row],[Edad]]<=50,"Adultos",INFO_Pasajeros[[#This Row],[Edad]]>=51,"Adultos Mayores")} -> Adultos
A671: Rommetvedt, Mr. Knud Paust | B671: male | C671: 668 | D671: 39 | E671: 0 | F671: 0 | G671: 3 | H671: 0 | I671: A/4 48871 | J671: 7.775 | K671: Desconocido | L671: S | M671: {=_xlfn.IFS(INFO_Pasajeros[[#This Row],[Edad]]<=13,"Niños",INFO_Pasajeros[[#This Row],[Edad]]<=18,"Jóvenes",INFO_Pasajeros[[#This Row],[Edad]]<=50,"Adultos",INFO_Pasajeros[[#This Row],[Edad]]>=51,"Adultos Mayores")} -> Adultos
A672: Cook, Mr. Jacob | B672: male | C672: 669 | D672: 16 | E672: 0 | F672: 0 | G672: 3 | H672: 0 | I672: A/4. 20589 | J672: 8.05 | K672: Desconocido | L672: S | M672: {=_xlfn.IFS(INFO_Pasajeros[[#This Row],[Edad]]<=13,"Niños",INFO_Pasajeros[[#This Row],[Edad]]<=18,"Jóvenes",INFO_Pasajeros[[#This Row],[Edad]]<=50,"Adultos",INFO_Pasajeros[[#This Row],[Edad]]>=51,"Adultos Mayores")} -> Jóvenes
A673: Taylor, Mrs. Elmer Zebley (Juliet Cummins Wright) | B673: female | C673: 670 | D673: 20 | E673: 0 | F673: 1 | G673: 1 | H673: 1 | I673: A/4. 34244 | J673: 52 | K673: Desconocido | L673: S | M673: {=_xlfn.IFS(INFO_Pasajeros[[#This Row],[Edad]]<=13,"Niños",INFO_Pasajeros[[#This Row],[Edad]]<=18,"Jóvenes",INFO_Pasajeros[[#This Row],[Edad]]<=50,"Adultos",INFO_Pasajeros[[#This Row],[Edad]]>=51,"Adultos Mayores")} -> Adultos
A674: Brown, Mrs. Thomas William Solomon (Elizabeth Catherine Ford) | B674: female | C674: 671 | D674: 21 | E674: 1 | F674: 1 | G674: 2 | H674: 1 | I674: A/4. 39886 | J674: 39 | K674: Desconocido | L674: S | M674: {=_xlfn.IFS(INFO_Pasajeros[[#This Row],[Edad]]<=13,"Niños",INFO_Pasajeros[[#This Row],[Edad]]<=18,"Jóvenes",INFO_Pasajeros[[#This Row],[Edad]]<=50,"Adultos",INFO_Pasajeros[[#This Row],[Edad]]>=51,"Adultos Mayores")} -> Adultos
A675: Davidson, Mr. Thornton | B675: male | C675: 672 | D675: 22 | E675: 0 | F675: 1 | G675: 1 | H675: 0 | I675: A/5 21171 | J675: 52 | K675: Desconocido | L675: S | M675: {=_xlfn.IFS(INFO_Pasajeros[[#This Row],[Edad]]<=13,"Niños",INFO_Pasajeros[[#This Row],[Edad]]<=18,"Jóvenes",INFO_Pasajeros[[#This Row],[Edad]]<=50,"Adultos",INFO_Pasajeros[[#This Row],[Edad]]>=51,"Adultos Mayores")} -> Adultos
A676: Mitchell, Mr. Henry Michael | B676: male | C676: 673 | D676: 22 | E676: 0 | F676: 0 | G676: 2 | H676: 0 | I676: A/5 21172 | J676: 10.5 | K676: Desconocido | L676: S | M676: {=_xlfn.IFS(INFO_Pasajeros[[#This Row],[Edad]]<=13,"Niños",INFO_Pasajeros[[#This Row],[Edad]]<=18,"Jóvenes",INFO_Pasajeros[[#This Row],[Edad]]<=50,"Adultos",INFO_Pasajeros[[#This Row],[Edad]]>=51,"Adultos Mayores")} -> Adultos
... A894: Dooley, Mr. Patrick | B894: male | C894: 891 | D894: 70 | E894: 0 | F894: 0 | G894: 3 | H894: 0 | I894: WE/P 5735 | J894: 7.75 | K894: B22 | L894: S | M894: {=_xlfn.IFS(INFO_Pasajeros[[#This Row],[Edad]]<=13,"Niños",INFO_Pasajeros[[#This Row],[Edad]]<=18,"Jóvenes",INFO_Pasajeros[[#This Row],[Edad]]<=50,"Adultos",INFO_Pasajeros[[#This Row],[Edad]]>=51,"Adultos Mayores")} -> Adultos Mayores

Sheet Preguntas y Respuestas
A3: 1a).¿Cuántos Pasajeros había en total en el barco?, ¿Cuántos de ellos eran hombres y cuántos mujeres?.b)¿Qué porcentaje de cada uno hay respecto al total? | G3: RESPUESTA:a) El total de pasajeros registrador es de 891. De ellos 314 son mujeres y 577 son hombres.
A4: a) | B4: TOTAL | C4: SOBREVIVIENTES | D4: NO SOBREVIVIENTES | G4: Se observa mayor proporción de masculinos.
A5: Hombres: | B5: =COUNTIF(DATASET_CLEAN!B:B,"male") -> 577 | C5: =COUNTIFS(INFO_Pasajeros[Sexo],"male",INFO_Pasajeros[Sobreviviente],1) -> 109 | D5: =C5+C6 -> 342
A6: Mujeres: | B6: =COUNTIF(DATASET_CLEAN!B:B,"female") -> 314 | C6: =COUNTIFS(INFO_Pasajeros[Sexo],"female",INFO_Pasajeros[Sobreviviente],1) -> 233
A7: Total Pasajeros: | B7: =COUNTA(INFO_Pasajeros[Sexo]) -> 891
A8: b) | F8: RESPUESTA:b) Los hombres representan aproximadamente 65% del total. Mientras que las mujeres un 35%.
A9: Hombres: | B9: =COUNTIF(INFO_Pasajeros[Sexo],"male")/COUNTA(INFO_Pasajeros[Sexo]) -> 0.64758698 | C9: =ROUNDUP(B9,2) -> 0.65 | G9: Evidenciando una composición mayoritariamente masculina
A10: Mujeres: | B10: =COUNTIF(INFO_Pasajeros[Sexo],"female")/COUNTA(INFO_Pasajeros[Sexo]) -> 0.35241302 | C10: =ROUNDDOWN(B10,2) -> 0.35
A12: 2a).¿Existen diferencias en la edad promedio entre los pasarejos que sobrevivieron y los que no sobrevivieron? | F12: RESPUESTA a: La diferencia de edad promedio en ambos grupos es mínima lo que suguiere que la edad
G13: en términos generales, no fue un factor determinante por sí sola en la supervivencia.
A14: Edad Promedio: | B14: =AVERAGE(INFO_Pasajeros[Edad]) -> 31.937149 | C14: =ROUNDUP(B14,0) -> 32
A15: Edad Promedio Sobrevivientes: | B15: =AVERAGEIF(INFO_Pasajeros[Sobreviviente],1,INFO_Pasajeros[Edad]) -> 31.491228 | C15: =ROUNDDOWN(B15,1) -> 31.4
A16: Edad Promedio No Sobrevivientes: | B16: =AVERAGEIF(INFO_Pasajeros[Sobreviviente],0,INFO_Pasajeros[Edad]) -> 32.214936 | C16: =ROUNDDOWN(B16,1) -> 32.2
A18: 2b).Dado que la diferencia en la edad promedio entre sobrevivientes y no sobrevivientes es mínima, ¿Existen diferencias en la tasa de supervivencia al analizar la edad por rangos etarios? | H18: RESPUESTA b: Al segmentar por rangos de edad se observan variaciones en la tasa de supervivencia
I19: especialmente en determinados grupos etarios. Lo que indica que el análisis
A20: Rango etario | B20: TOTAL | C20: Sobrevivientes. | D20: No Sobrevivientes. | E20: Tasa de Supervivencia(%) | I20: por promedio general oculta diferencias internas relevantes
A21: Niños(0—12)): | B21: =COUNTIFS(INFO_Pasajeros[Edad],">=1",INFO_Pasajeros[Edad],"<=12") -> 96 | C21: =COUNTIFS(INFO_Pasajeros[Sobreviviente],"1",INFO_Pasajeros[Edad],">=0",INFO_Pasajeros[Edad],"<=12") -> 41 | D21: =B21-C21 -> 55 | E21: =C21/B21 -> 0.42708333
A22: Jóvenes(13—18): | B22: =COUNTIFS(INFO_Pasajeros[Edad],">=13",INFO_Pasajeros[Edad],"<=18") -> 75 | C22: =COUNTIFS(INFO_Pasajeros[Sobreviviente],"1",INFO_Pasajeros[Edad],">=13",INFO_Pasajeros[Edad],"<=18") -> 26 | D22: =B22-C22 -> 49 | E22: =C22/B22 -> 0.34666667
A23: Adultos(19—50): | B23: =COUNTIFS(INFO_Pasajeros[Edad],">=19",INFO_Pasajeros[Edad],"<=50") -> 593 | C23: =COUNTIFS(INFO_Pasajeros[Sobreviviente],"1",INFO_Pasajeros[Edad],">=19",INFO_Pasajeros[Edad],"<=50") -> 236 | D23: =B23-C23 -> 357 | E23: =C23/B23 -> 0.39797639
A24: Adultos Mayores(51+): | B24: =COUNTIF(INFO_Pasajeros[Edad],">=51") -> 127 | C24: =COUNTIFS(INFO_Pasajeros[Sobreviviente],"1",INFO_Pasajeros[Edad],">=51") -> 39 | D24: =B24-C24 -> 88 | E24: =C24/B24 -> 0.30708661
A27: 3.Tomando como ejemplo al pasajero "DeWitt Bukater, Miss. Rose", Mostrar:
A28: a)¿Qué clase de pasaje tenía?
A29: b)¿Sobrevivió?
B32: c) | C32: b) | D32: a)
B33: Nombre | C33: Sobrevivió | D33: Clase_De_Pasaje
A34: DeWitt Bukater, Miss. Rose | B34: {=CONCATENATE("Pasajero ",A34," de clase ",_xlfn.XLOOKUP(A34,INFO_Pasajeros[Nombre],INFO_Pasajeros[Clase_Del_Pasaje])," ",IF(_xlfn.XLOOKUP(A34,INFO_Pasajeros[Nombre],INFO_Pasajeros[Sobreviviente]=1),"Sobrevivió","No Sobrevivió"))} -> Pasajero DeWitt Bukater, Miss. Rose de clase 1 Sobrevivió | C34: {=IF(_xlfn.XLOOKUP('Preguntas y Respuestas'!A34,INFO_Pasajeros[Nombre],INFO_Pasajeros[Sobreviviente]=1),"Sobrevivió","No sobrevivió")} -> Sobrevivió | D34: =_xlfn.XLOOKUP(A34,INFO_Pasajeros[Nombre],INFO_Pasajeros[Clase_Del_Pasaje]) -> 1
A39: 4a)En cuestión de Tipos de pasaje. Teníamos Clase 1. Clase 2 Clase 3. ¿Cuántos había de cada uno? | F39: RESPUESTA a: La clase 3 concentra mayor cantidad de pasarejos, seguida por la clase 1 y luego la fclase 3. Lo que suguiere
F40: una relación directa entre categoría de pasaje y probabildiad de supervivencia.
A41: b)¿Cuántos tripulantes de cada clase lograron sobrevivir? | F41: RESPUESTA b: La tasa de supervivencia es significativamente mayor en la Clase 1 en comparación con las Clases 2 y 3.
F42: Lo que suigiere una relación directa entre categoría de pasaje y posibilidad de supervivencia.
A43: c)¿Qué porcentaje de cada uno nos da? | F43: RESPUESTA c: En todas las clases de observa una mayor tasa de supervivencia femenina en comparación con la masculina.
G44: Esto refuerza el patron general de priorización por sexo.
A45: a.
A46: Tipos de Pasaje | B46: Clase 1 | C46: Clase 2 | D46: Clase 3
A47: Cantidad | B47: =COUNTIF(INFO_Pasajeros[Clase_Del_Pasaje],"1") -> 216 | C47: =COUNTIF(INFO_Pasajeros[Clase_Del_Pasaje],2) -> 184 | D47: =COUNTIF(INFO_Pasajeros[Clase_Del_Pasaje],3) -> 491
A48: b.
A49: Sobrevivientes por Clase | B49: =COUNTIFS(INFO_Pasajeros[Clase_Del_Pasaje],1,INFO_Pasajeros[Sobreviviente],1) -> 136 | C49: =COUNTIFS(INFO_Pasajeros[Clase_Del_Pasaje],2,INFO_Pasajeros[Sobreviviente],1) -> 87 | D49: =COUNTIFS(INFO_Pasajeros[Clase_Del_Pasaje],3,INFO_Pasajeros[Sobreviviente],1) -> 119
A50: c.
A51: Porcentaje de sobrevivientes | B51: =B49/B47 -> 0.62962963 | C51: =C49/C47 -> 0.47282609 | D51: =D49/D47 -> 0.24236253
A54: 5.Dentro de cada Clase.¿Cuál es la tasa de supervivencia según el sexo? | F54: RESPUESTA: La tasa de supervivencia según el sexo, tiene mucha amplitud en torno al grupo femenino. Esto se debe a la priorización
...

Sheet AUXILIAR
A3: VALIDACIONES | D3: Total Tripulantes | E3: Total Sobrevivientes | F3: Etiquetas de fila | G3: Cuenta de Clase_Del_Pasaje | I3: Clase de Pasaje | J3: Sobrevivientes | L3: Cuenta de Sobreviviente | M3: Etiquetas de columna
A4: Lista_Sexo | B4: Lista_Embarque | D4: =COUNT(INFO_Pasajeros[ID_Pasajero]) -> 891 | E4: 109 | F4: 1 | G4: 122 | I4: 1 | J4: 45 | L4: Embarque | M4: Fallecidos | N4: Sobrevivientes | O4: Total general
A5: male | B5: S | D5: =COUNTIF(INFO_Pasajeros[Sexo],"male") -> 577 | E5: ='Preguntas y Respuestas'!C5 -> 109 | F5: 2 | G5: 108 | I5: 2 | J5: 17 | L5: C | M5: 86 | N5: 22 | O5: 108
A6: female | B6: C | D6: =COUNTIF(INFO_Pasajeros[Sexo],"female") -> 314 | E6: ='Preguntas y Respuestas'!C6 -> 233 | F6: 3 | G6: 347 | I6: 3 | J6: 47 | L6: Q | M6: 40 | N6: 8 | O6: 48
B7: Q | F7: Total general | G7: 577 | I7: Total general | J7: 109 | L7: S | M7: 342 | N7: 79 | O7: 421
L8: Total general | M8: 468 | N8: 109 | O8: 577
A9: Adición de pasajero
A10: DeWitt Bukater, Miss. Rose
A11: Tarifa_Max | B11: Total_Clase | C11: Mediana_X_Clas | E11: Clase | F11: Tripulantes
A12: Clase 1 | B12: =_xlfn.MAXIFS(INFO_Pasajeros[Tarifa],INFO_Pasajeros[Clase_Del_Pasaje],1) -> 910.792 | C12: {=MEDIAN(_xlfn._xlws.FILTER(INFO_Pasajeros[Tarifa],INFO_Pasajeros[Clase_Del_Pasaje]=1))} -> 107.6625 | E12: Clase 1 | F12: =COUNTIF(INFO_Pasajeros[Clase_Del_Pasaje],1) -> 216 | L12: Etiquetas de fila | M12: Suma de Sobreviviente
A13: Clase 2 | B13: =_xlfn.MAXIFS(INFO_Pasajeros[Tarifa],INFO_Pasajeros[Clase_Del_Pasaje],2) -> 415.792 | C13: {=MEDIAN(_xlfn._xlws.FILTER(INFO_Pasajeros[Tarifa],INFO_Pasajeros[Clase_Del_Pasaje]=2))} -> 15.025 | E13: Clase 2 | F13: =COUNTIF(INFO_Pasajeros[Clase_Del_Pasaje],2) -> 184 | L13: Adultos
A14: Clase 3 | B14: =_xlfn.MAXIFS(INFO_Pasajeros[Tarifa],INFO_Pasajeros[Clase_Del_Pasaje],3) -> 564.958 | C14: =MEDIAN(_xlfn._xlws.FILTER(INFO_Pasajeros[Tarifa],INFO_Pasajeros[Clase_Del_Pasaje],3)) -> 29.125 | E14: Clase 3 | F14: =COUNTIF(INFO_Pasajeros[Clase_Del_Pasaje],3) -> 491 | L14: 1 | M14: 94
L15: 2 | M15: 58
G16: Rango Etario | H16: Sobrevivientes | L16: 3 | M16: 84
G17: Edad | H17: No | I17: Si | J17: Total general | L17: Adultos Mayores
G18: 0-9 | H18: 39 | I18: 12 | J18: 51 | L18: 1 | M18: 15
G19: 10-19 | H19: 59 | I19: 15 | J19: 74 | L19: 2 | M19: 10
G20: 20-29 | H20: 135 | I20: 29 | J20: 164 | L20: 3 | M20: 14
G21: 30-39 | H21: 98 | I21: 23 | J21: 121 | L21: Jóvenes
A22: Etiquetas de fila | B22: Promedio de Sobreviviente | D22: Clase | E22: Promedio de Tarifa | G22: 40-49 | H22: 59 | I22: 10 | J22: 69 | L22: 1 | M22: 11
A23: Hombres | B23: 0.18890815 | D23: 1 | E23: 184.12961 | G23: 50-59 | H23: 39 | I23: 11 | J23: 50 | L23: 2 | M23: 7
A24: Total general | B24: 0.18890815 | D24: 2 | E24: 36.599074 | G24: 60-69 | H24: 22 | I24: 6 | J24: 28 | L24: 3 | M24: 7
D25: 3 | E25: 59.090389 | G25: 70-80 | H25: 17 | I25: 3 | J25: 20 | L25: Niños
D26: Promedio General | E26: 81.318679 | G26: Total general | H26: 468 | I26: 109 | J26: 577 | L26: 1 | M26: 16
L27: 2 | M27: 12
L28: 3 | M28: 14
A29: FALLECIDOS | L29: Total general | M29: 342
A30: =COUNTIF(INFO_Pasajeros[Sobreviviente],0) -> 549

Sheet Chequeo_Fare
A1: Fare correción 3 | B1: Fare correción 2 | C1: Fare corrección | D1: Fare
A2: =IF(Tabla3[[#This Row],[Fare correción 2]]>=1000,Tabla3[[#This Row],[Fare correción 2]]/10,Tabla3[[#This Row],[Fare correción 2]]) -> 7.25 | B2: =IF(Tabla3[[#This Row],[Fare corrección]]>1000,Tabla3[[#This Row],[Fare corrección]]/1000,Tabla3[[#This Row],[Fare corrección]]) -> 7.25 | C2: =IF(ISNUMBER(Tabla3[[#This Row],[Fare]]),Tabla3[[#This Row],[Fare]],VALUE(SUBSTITUTE(Tabla3[[#This Row],[Fare]],".",","))) -> 7.25 | D2: 7.25
A3: =IF(Tabla3[[#This Row],[Fare correción 2]]>=1000,Tabla3[[#This Row],[Fare correción 2]]/10,Tabla3[[#This Row],[Fare correción 2]]) -> 712.833 | B3: =IF(Tabla3[[#This Row],[Fare corrección]]>1000,Tabla3[[#This Row],[Fare corrección]]/1000,Tabla3[[#This Row],[Fare corrección]]) -> 712.833 | C3: =IF(ISNUMBER(Tabla3[[#This Row],[Fare]]),Tabla3[[#This Row],[Fare]],VALUE(SUBSTITUTE(Tabla3[[#This Row],[Fare]],".",","))) -> 712833 | D3: 712833 | E3: (=MAX FC2) | F3: =MAX(Tabla3[Fare correción 2]) -> 5123.292
A4: =IF(Tabla3[[#This Row],[Fare correción 2]]>=1000,Tabla3[[#This Row],[Fare correción 2]]/10,Tabla3[[#This Row],[Fare correción 2]]) -> 7.925 | B4: =IF(Tabla3[[#This Row],[Fare corrección]]>1000,Tabla3[[#This Row],[Fare corrección]]/1000,Tabla3[[#This Row],[Fare corrección]]) -> 7.925 | C4: =IF(ISNUMBER(Tabla3[[#This Row],[Fare]]),Tabla3[[#This Row],[Fare]],VALUE(SUBSTITUTE(Tabla3[[#This Row],[Fare]],".",","))) -> 7925 | D4: 7925 | E4: (MAX FC3) | F4: =MAX(Tabla3[Fare correción 3]) -> 910.792
A5: =IF(Tabla3[[#This Row],[Fare correción 2]]>=1000,Tabla3[[#This Row],[Fare correción 2]]/10,Tabla3[[#This Row],[Fare correción 2]]) -> 53.1 | B5: =IF(Tabla3[[#This Row],[Fare corrección]]>1000,Tabla3[[#This Row],[Fare corrección]]/1000,Tabla3[[#This Row],[Fare corrección]]) -> 53.1 | C5: =IF(ISNUMBER(Tabla3[[#This Row],[Fare]]),Tabla3[[#This Row],[Fare]],VALUE(SUBSTITUTE(Tabla3[[#This Row],[Fare]],".",","))) -> 53.1 | D5: 53.1
A6: =IF(Tabla3[[#This Row],[Fare correción 2]]>=1000,Tabla3[[#This Row],[Fare correción 2]]/10,Tabla3[[#This Row],[Fare correción 2]]) -> 8.05 | B6: =IF(Tabla3[[#This Row],[Fare corrección]]>1000,Tabla3[[#This Row],[Fare corrección]]/1000,Tabla3[[#This Row],[Fare corrección]]) -> 8.05 | C6: =IF(ISNUMBER(Tabla3[[#This Row],[Fare]]),Tabla3[[#This Row],[Fare]],VALUE(SUBSTITUTE(Tabla3[[#This Row],[Fare]],".",","))) -> 8.05 | D6: 8.05
A7: =IF(Tabla3[[#This Row],[Fare correción 2]]>=1000,Tabla3[[#This Row],[Fare correción 2]]/10,Tabla3[[#This Row],[Fare correción 2]]) -> 84.583 | B7: =IF(Tabla3[[#This Row],[Fare corrección]]>1000,Tabla3[[#This Row],[Fare corrección]]/1000,Tabla3[[#This Row],[Fare corrección]]) -> 84.583 | C7: =IF(ISNUMBER(Tabla3[[#This Row],[Fare]]),Tabla3[[#This Row],[Fare]],VALUE(SUBSTITUTE(Tabla3[[#This Row],[Fare]],".",","))) -> 84583 | D7: 84583
A8: =IF(Tabla3[[#This Row],[Fare correción 2]]>=1000,Tabla3[[#This Row],[Fare correción 2]]/10,Tabla3[[#This Row],[Fare correción 2]]) -> 518.625 | B8: =IF(Tabla3[[#This Row],[Fare corrección]]>1000,Tabla3[[#This Row],[Fare corrección]]/1000,Tabla3[[#This Row],[Fare corrección]]) -> 518.625 | C8: =IF(ISNUMBER(Tabla3[[#This Row],[Fare]]),Tabla3[[#This Row],[Fare]],VALUE(SUBSTITUTE(Tabla3[[#This Row],[Fare]],".",","))) -> 518625 | D8: 518625
A9: =IF(Tabla3[[#This Row],[Fare correción 2]]>=1000,Tabla3[[#This Row],[Fare correción 2]]/10,Tabla3[[#This Row],[Fare correción 2]]) -> 21.075 | B9: =IF(Tabla3[[#This Row],[Fare corrección]]>1000,Tabla3[[#This Row],[Fare corrección]]/1000,Tabla3[[#This Row],[Fare corrección]]) -> 21.075 | C9: =IF(ISNUMBER(Tabla3[[#This Row],[Fare]]),Tabla3[[#This Row],[Fare]],VALUE(SUBSTITUTE(Tabla3[[#This Row],[Fare]],".",","))) -> 21075 | D9: 21075
A10: =IF(Tabla3[[#This Row],[Fare correción 2]]>=1000,Tabla3[[#This Row],[Fare correción 2]]/10,Tabla3[[#This Row],[Fare correción 2]]) -> 111.333 | B10: =IF(Tabla3[[#This Row],[Fare corrección]]>1000,Tabla3[[#This Row],[Fare corrección]]/1000,Tabla3[[#This Row],[Fare corrección]]) -> 111.333 | C10: =IF(ISNUMBER(Tabla3[[#This Row],[Fare]]),Tabla3[[#This Row],[Fare]],VALUE(SUBSTITUTE(Tabla3[[#This Row],[Fare]],".",","))) -> 111333 | D10: 111333
A11: =IF(Tabla3[[#This Row],[Fare correción 2]]>=1000,Tabla3[[#This Row],[Fare correción 2]]/10,Tabla3[[#This Row],[Fare correción 2]]) -> 300.708 | B11: =IF(Tabla3[[#This Row],[Fare corrección]]>1000,Tabla3[[#This Row],[Fare corrección]]/1000,Tabla3[[#This Row],[Fare corrección]]) -> 300.708 | C11: =IF(ISNUMBER(Tabla3[[#This Row],[Fare]]),Tabla3[[#This Row],[Fare]],VALUE(SUBSTITUTE(Tabla3[[#This Row],[Fare]],".",","))) -> 300708 | D11: 300708
A12: =IF(Tabla3[[#This Row],[Fare correción 2]]>=1000,Tabla3[[#This Row],[Fare correción 2]]/10,Tabla3[[#This Row],[Fare correción 2]]) -> 16.7 | B12: =IF(Tabla3[[#This Row],[Fare corrección]]>1000,Tabla3[[#This Row],[Fare corrección]]/1000,Tabla3[[#This Row],[Fare corrección]]) -> 16.7 | C12: =IF(ISNUMBER(Tabla3[[#This Row],[Fare]]),Tabla3[[#This Row],[Fare]],VALUE(SUBSTITUTE(Tabla3[[#This Row],[Fare]],".",","))) -> 16.7 | D12: 16.7
A13: =IF(Tabla3[[#This Row],[Fare correción 2]]>=1000,Tabla3[[#This Row],[Fare correción 2]]/10,Tabla3[[#This Row],[Fare correción 2]]) -> 26.55 | B13: =IF(Tabla3[[#This Row],[Fare corrección]]>1000,Tabla3[[#This Row],[Fare corrección]]/1000,Tabla3[[#This Row],[Fare corrección]]) -> 26.55 | C13: =IF(ISNUMBER(Tabla3[[#This Row],[Fare]]),Tabla3[[#This Row],[Fare]],VALUE(SUBSTITUTE(Tabla3[[#This Row],[Fare]],".",","))) -> 26.55 | D13: 26.55
A14: =IF(Tabla3[[#This Row],[Fare correción 2]]>=1000,Tabla3[[#This Row],[Fare correción 2]]/10,Tabla3[[#This Row],[Fare correción 2]]) -> 8.05 | B14: =IF(Tabla3[[#This Row],[Fare corrección]]>1000,Tabla3[[#This Row],[Fare corrección]]/1000,Tabla3[[#This Row],[Fare corrección]]) -> 8.05 | C14: =IF(ISNUMBER(Tabla3[[#This Row],[Fare]]),Tabla3[[#This Row],[Fare]],VALUE(SUBSTITUTE(Tabla3[[#This Row],[Fare]],".",","))) -> 8.05 | D14: 8.05
A15: =IF(Tabla3[[#This Row],[Fare correción 2]]>=1000,Tabla3[[#This Row],[Fare correción 2]]/10,Tabla3[[#This Row],[Fare correción 2]]) -> 31.275 | B15: =IF(Tabla3[[#This Row],[Fare corrección]]>1000,Tabla3[[#This Row],[Fare corrección]]/1000,Tabla3[[#This Row],[Fare corrección]]) -> 31.275 | C15: =IF(ISNUMBER(Tabla3[[#This Row],[Fare]]),Tabla3[[#This Row],[Fare]],VALUE(SUBSTITUTE(Tabla3[[#This Row],[Fare]],".",","))) -> 31275 | D15: 31275
A16: =IF(Tabla3[[#This Row],[Fare correción 2]]>=1000,Tabla3[[#This Row],[Fare correción 2]]/10,Tabla3[[#This Row],[Fare correción 2]]) -> 78.542 | B16: =IF(Tabla3[[#This Row],[Fare corrección]]>1000,Tabla3[[#This Row],[Fare corrección]]/1000,Tabla3[[#This Row],[Fare corrección]]) -> 78.542 | C16: =IF(ISNUMBER(Tabla3[[#This Row],[Fare]]),Tabla3[[#This Row],[Fare]],VALUE(SUBSTITUTE(Tabla3[[#This Row],[Fare]],".",","))) -> 78542 | D16: 78542
A17: =IF(Tabla3[[#This Row],[Fare correción 2]]>=1000,Tabla3[[#This Row],[Fare correción 2]]/10,Tabla3[[#This Row],[Fare correción 2]]) -> 16 | B17: =IF(Tabla3[[#This Row],[Fare corrección]]>1000,Tabla3[[#This Row],[Fare corrección]]/1000,Tabla3[[#This Row],[Fare corrección]]) -> 16 | C17: =IF(ISNUMBER(Tabla3[[#This Row],[Fare]]),Tabla3[[#This Row],[Fare]],VALUE(SUBSTITUTE(Tabla3[[#This Row],[Fare]],".",","))) -> 16 | D17: 16
A18: =IF(Tabla3[[#This Row],[Fare correción 2]]>=1000,Tabla3[[#This Row],[Fare correción 2]]/10,Tabla3[[#This Row],[Fare correción 2]]) -> 29.125 | B18: =IF(Tabla3[[#This Row],[Fare corrección]]>1000,Tabla3[[#This Row],[Fare corrección]]/1000,Tabla3[[#This Row],[Fare corrección]]) -> 29.125 | C18: =IF(ISNUMBER(Tabla3[[#This Row],[Fare]]),Tabla3[[#This Row],[Fare]],VALUE(SUBSTITUTE(Tabla3[[#This Row],[Fare]],".",","))) -> 29125 | D18: 29125
A19: =IF(Tabla3[[#This Row],[Fare correción 2]]>=1000,Tabla3[[#This Row],[Fare correción 2]]/10,Tabla3[[#This Row],[Fare correción 2]]) -> 13 | B19: =IF(Tabla3[[#This Row],[Fare corrección]]>1000,Tabla3[[#This Row],[Fare corrección]]/1000,Tabla3[[#This Row],[Fare corrección]]) -> 13 | C19: =IF(ISNUMBER(Tabla3[[#This Row],[Fare]]),Tabla3[[#This Row],[Fare]],VALUE(SUBSTITUTE(Tabla3[[#This Row],[Fare]],".",","))) -> 13 | D19: 13
A20: =IF(Tabla3[[#This Row],[Fare correción 2]]>=1000,Tabla3[[#This Row],[Fare correción 2]]/10,Tabla3[[#This Row],[Fare correción 2]]) -> 18 | B20: =IF(Tabla3[[#This Row],[Fare corrección]]>1000,Tabla3[[#This Row],[Fare corrección]]/1000,Tabla3[[#This Row],[Fare corrección]]) -> 18 | C20: =IF(ISNUMBER(Tabla3[[#This Row],[Fare]]),Tabla3[[#This Row],[Fare]],VALUE(SUBSTITUTE(Tabla3[[#This Row],[Fare]],".",","))) -> 18 | D20: 18
A21: =IF(Tabla3[[#This Row],[Fare correción 2]]>=1000,Tabla3[[#This Row],[Fare correción 2]]/10,Tabla3[[#This Row],[Fare correción 2]]) -> 7.225 | B21: =IF(Tabla3[[#This Row],[Fare corrección]]>1000,Tabla3[[#This Row],[Fare corrección]]/1000,Tabla3[[#This Row],[Fare corrección]]) -> 7.225 | C21: =IF(ISNUMBER(Tabla3[[#This Row],[Fare]]),Tabla3[[#This Row],[Fare]],VALUE(SUBSTITUTE(Tabla3[[#This Row],[Fare]],".",","))) -> 7225 | D21: 7225
A22: =IF(Tabla3[[#This Row],[Fare correción 2]]>=1000,Tabla3[[#This Row],[Fare correción 2]]/10,Tabla3[[#This Row],[Fare correción 2]]) -> 26 | B22: =IF(Tabla3[[#This Row],[Fare corrección]]>1000,Tabla3[[#This Row],[Fare corrección]]/1000,Tabla3[[#This Row],[Fare corrección]]) -> 26 | C22: =IF(ISNUMBER(Tabla3[[#This Row],[Fare]]),Tabla3[[#This Row],[Fare]],VALUE(SUBSTITUTE(Tabla3[[#This Row],[Fare]],".",","))) -> 26 | D22: 26
A23: =IF(Tabla3[[#This Row],[Fare correción 2]]>=1000,Tabla3[[#This Row],[Fare correción 2]]/10,Tabla3[[#This Row],[Fare correción 2]]) -> 13 | B23: =IF(Tabla3[[#This Row],[Fare corrección]]>1000,Tabla3[[#This Row],[Fare corrección]]/1000,Tabla3[[#This Row],[Fare corrección]]) -> 13 | C23: =IF(ISNUMBER(Tabla3[[#This Row],[Fare]]),Tabla3[[#This Row],[Fare]],VALUE(SUBSTITUTE(Tabla3[[#This Row],[Fare]],".",","))) -> 13 | D23: 13
A24: =IF(Tabla3[[#This Row],[Fare correción 2]]>=1000,Tabla3[[#This Row],[Fare correción 2]]/10,Tabla3[[#This Row],[Fare correción 2]]) -> 80.292 | B24: =IF(Tabla3[[#This Row],[Fare corrección]]>1000,Tabla3[[#This Row],[Fare corrección]]/1000,Tabla3[[#This Row],[Fare corrección]]) -> 80.292 | C24: =IF(ISNUMBER(Tabla3[[#This Row],[Fare]]),Tabla3[[#This Row],[Fare]],VALUE(SUBSTITUTE(Tabla3[[#This Row],[Fare]],".",","))) -> 80292 | D24: 80292
A25: =IF(Tabla3[[#This Row],[Fare correción 2]]>=1000,Tabla3[[#This Row],[Fare correción 2]]/10,Tabla3[[#This Row],[Fare correción 2]]) -> 35.5 | B25: =IF(Tabla3[[#This Row],[Fare corrección]]>1000,Tabla3[[#This Row],[Fare corrección]]/1000,Tabla3[[#This Row],[Fare corrección]]) -> 35.5 | C25: =IF(ISNUMBER(Tabla3[[#This Row],[Fare]]),Tabla3[[#This Row],[Fare]],VALUE(SUBSTITUTE(Tabla3[[#This Row],[Fare]],".",","))) -> 35.5 | D25: 35.5
A26: =IF(Tabla3[[#This Row],[Fare correción 2]]>=1000,Tabla3[[#This Row],[Fare correción 2]]/10,Tabla3[[#This Row],[Fare correción 2]]) -> 21.075 | B26: =IF(Tabla3[[#This Row],[Fare corrección]]>1000,Tabla3[[#This Row],[Fare corrección]]/1000,Tabla3[[#This Row],[Fare corrección]]) -> 21.075 | C26: =IF(ISNUMBER(Tabla3[[#This Row],[Fare]]),Tabla3[[#This Row],[Fare]],VALUE(SUBSTITUTE(Tabla3[[#This Row],[Fare]],".",","))) -> 21075 | D26: 21075
A27: =IF(Tabla3[[#This Row],[Fare correción 2]]>=1000,Tabla3[[#This Row],[Fare correción 2]]/10,Tabla3[[#This Row],[Fare correción 2]]) -> 313.875 | B27: =IF(Tabla3[[#This Row],[Fare corrección]]>1000,Tabla3[[#This Row],[Fare corrección]]/1000,Tabla3[[#This Row],[Fare corrección]]) -> 313.875 | C27: =IF(ISNUMBER(Tabla3[[#This Row],[Fare]]),Tabla3[[#This Row],[Fare]],VALUE(SUBSTITUTE(Tabla3[[#This Row],[Fare]],".",","))) -> 313875 | D27: 313875
A28: =IF(Tabla3[[#This Row],[Fare correción 2]]>=1000,Tabla3[[#This Row],[Fare correción 2]]/10,Tabla3[[#This Row],[Fare correción 2]]) -> 7.225 | B28: =IF(Tabla3[[#This Row],[Fare corrección]]>1000,Tabla3[[#This Row],[Fare corrección]]/1000,Tabla3[[#This Row],[Fare corrección]]) -> 7.225 | C28: =IF(ISNUMBER(Tabla3[[#This Row],[Fare]]),Tabla3[[#This Row],[Fare]],VALUE(SUBSTITUTE(Tabla3[[#This Row],[Fare]],".",","))) -> 7225 | D28: 7225
A29: =IF(Tabla3[[#This Row],[Fare correción 2]]>=1000,Tabla3[[#This Row],[Fare correción 2]]/10,Tabla3[[#This Row],[Fare correción 2]]) -> 263 | B29: =IF(Tabla3[[#This Row],[Fare corrección]]>1000,Tabla3[[#This Row],[Fare corrección]]/1000,Tabla3[[#This Row],[Fare corrección]]) -> 263 | C29: =IF(ISNUMBER(Tabla3[[#This Row],[Fare]]),Tabla3[[#This Row],[Fare]],VALUE(SUBSTITUTE(Tabla3[[#This Row],[Fare]],".",","))) -> 263 | D29: 263
A30: =IF(Tabla3[[#This Row],[Fare correción 2]]>=1000,Tabla3[[#This Row],[Fare correción 2]]/10,Tabla3[[#This Row],[Fare correción 2]]) -> 78.792 | B30: =IF(Tabla3[[#This Row],[Fare corrección]]>1000,Tabla3[[#This Row],[Fare corrección]]/1000,Tabla3[[#This Row],[Fare corrección]]) -> 78.792 | C30: =IF(ISNUMBER(Tabla3[[#This Row],[Fare]]),Tabla3[[#This Row],[Fare]],VALUE(SUBSTITUTE(Tabla3[[#This Row],[Fare]],".",","))) -> 78792 | D30: 78792
A31: =IF(Tabla3[[#This Row],[Fare correción 2]]>=1000,Tabla3[[#This Row],[Fare correción 2]]/10,Tabla3[[#This Row],[Fare correción 2]]) -> 78.958 | B31: =IF(Tabla3[[#This Row],[Fare corrección]]>1000,Tabla3[[#This Row],[Fare corrección]]/1000,Tabla3[[#This Row],[Fare corrección]]) -> 78.958 | C31: =IF(ISNUMBER(Tabla3[[#This Row],[Fare]]),Tabla3[[#This Row],[Fare]],VALUE(SUBSTITUTE(Tabla3[[#This Row],[Fare]],".",","))) -> 78958 | D31: 78958
A32: =IF(Tabla3[[#This Row],[Fare correción 2]]>=1000,Tabla3[[#This Row],[Fare correción 2]]/10,Tabla3[[#This Row],[Fare correción 2]]) -> 277.208 | B32: =IF(Tabla3[[#This Row],[Fare corrección]]>1000,Tabla3[[#This Row],[Fare corrección]]/1000,Tabla3[[#This Row],[Fare corrección]]) -> 277.208 | C32: =IF(ISNUMBER(Tabla3[[#This Row],[Fare]]),Tabla3[[#This Row],[Fare]],VALUE(SUBSTITUTE(Tabla3[[#This Row],[Fare]],".",","))) -> 277208 | D32: 277208
A33: =IF(Tabla3[[#This Row],[Fare correción 2]]>=1000,Tabla3[[#This Row],[Fare correción 2]]/10,Tabla3[[#This Row],[Fare correción 2]]) -> 146.5208 | B33: =IF(Tabla3[[#This Row],[Fare corrección]]>1000,Tabla3[[#This Row],[Fare corrección]]/1000,Tabla3[[#This Row],[Fare corrección]]) -> 1465.208 | C33: =IF(ISNUMBER(Tabla3[[#This Row],[Fare]]),Tabla3[[#This Row],[Fare]],VALUE(SUBSTITUTE(Tabla3[[#This Row],[Fare]],".",","))) -> 1465208 | D33: 1465208
A34: =IF(Tabla3[[#This Row],[Fare correción 2]]>=1000,Tabla3[[#This Row],[Fare correción 2]]/10,Tabla3[[#This Row],[Fare correción 2]]) -> 7.75 | B34: =IF(Tabla3[[#This Row],[Fare corrección]]>1000,Tabla3[[#This Row],[Fare corrección]]/1000,Tabla3[[#This Row],[Fare corrección]]) -> 7.75 | C34: =IF(ISNUMBER(Tabla3[[#This Row],[Fare]]),Tabla3[[#This Row],[Fare]],VALUE(SUBSTITUTE(Tabla3[[#This Row],[Fare]],".",","))) -> 7.75 | D34: 7.75
A35: =IF(Tabla3[[#This Row],[Fare correción 2]]>=1000,Tabla3[[#This Row],[Fare correción 2]]/10,Tabla3[[#This Row],[Fare correción 2]]) -> 10.5 | B35: =IF(Tabla3[[#This Row],[Fare corrección]]>1000,Tabla3[[#This Row],[Fare corrección]]/1000,Tabla3[[#This Row],[Fare corrección]]) -> 10.5 | C35: =IF(ISNUMBER(Tabla3[[#This Row],[Fare]]),Tabla3[[#This Row],[Fare]],VALUE(SUBSTITUTE(Tabla3[[#This Row],[Fare]],".",","))) -> 10.5 | D35: 10.5
A36: =IF(Tabla3[[#This Row],[Fare correción 2]]>=1000,Tabla3[[#This Row],[Fare correción 2]]/10,Tabla3[[#This Row],[Fare correción 2]]) -> 821.708 | B36: =IF(Tabla3[[#This Row],[Fare corrección]]>1000,Tabla3[[#This Row],[Fare corrección]]/1000,Tabla3[[#This Row],[Fare corrección]]) -> 821.708 | C36: =IF(ISNUMBER(Tabla3[[#This Row],[Fare]]),Tabla3[[#This Row],[Fare]],VALUE(SUBSTITUTE(Tabla3[[#This Row],[Fare]],".",","))) -> 821708 | D36: 821708
A37: =IF(Tabla3[[#This Row],[Fare correción 2]]>=1000,Tabla3[[#This Row],[Fare correción 2]]/10,Tabla3[[#This Row],[Fare correción 2]]) -> 52 | B37: =IF(Tabla3[[#This Row],[Fare corrección]]>1000,Tabla3[[#This Row],[Fare corrección]]/1000,Tabla3[[#This Row],[Fare corrección]]) -> 52 | C37: =IF(ISNUMBER(Tabla3[[#This Row],[Fare]]),Tabla3[[#This Row],[Fare]],VALUE(SUBSTITUTE(Tabla3[[#This Row],[Fare]],".",","))) -> 52 | D37: 52
A38: =IF(Tabla3[[#This Row],[Fare correción 2]]>=1000,Tabla3[[#This Row],[Fare correción 2]]/10,Tabla3[[#This Row],[Fare correción 2]]) -> 72.292 | B38: =IF(Tabla3[[#This Row],[Fare corrección]]>1000,Tabla3[[#This Row],[Fare corrección]]/1000,Tabla3[[#This Row],[Fare corrección]]) -> 72.292 | C38: =IF(ISNUMBER(Tabla3[[#This Row],[Fare]]),Tabla3[[#This Row],[Fare]],VALUE(SUBSTITUTE(Tabla3[[#This Row],[Fare]],".",","))) -> 72292 | D38: 72292
A39: =IF(Tabla3[[#This Row],[Fare correción 2]]>=1000,Tabla3[[#This Row],[Fare correción 2]]/10,Tabla3[[#This Row],[Fare correción 2]]) -> 8.05 | B39: =IF(Tabla3[[#This Row],[Fare corrección]]>1000,Tabla3[[#This Row],[Fare corrección]]/1000,Tabla3[[#This Row],[Fare corrección]]) -> 8.05 | C39: =IF(ISNUMBER(Tabla3[[#This Row],[Fare]]),Tabla3[[#This Row],[Fare]],VALUE(SUBSTITUTE(Tabla3[[#This Row],[Fare]],".",","))) -> 8.05 | D39: 8.05
A40: =IF(Tabla3[[#This Row],[Fare correción 2]]>=1000,Tabla3[[#This Row],[Fare correción 2]]/10,Tabla3[[#This Row],[Fare correción 2]]) -> 18 | B40: =IF(Tabla3[[#This Row],[Fare corrección]]>1000,Tabla3[[#This Row],[Fare corrección]]/1000,Tabla3[[#This Row],[Fare corrección]]) -> 18 | C40: =IF(ISNUMBER(Tabla3[[#This Row],[Fare]]),Tabla3[[#This Row],[Fare]],VALUE(SUBSTITUTE(Tabla3[[#This Row],[Fare]],".",","))) -> 18 | D40: 18
...

Sheet DASHBOARD
N3: ANÁLISIS DE SUPERVIVENCIA — TITANIC
N5: Resumen estadistico de pasajeros y tasas de supervivencia
M7: TOTAL DE PASAJEROS | N7: TOTAL SOBREVIVIENTES | O7: TASA DE SUPERVIVENCIA
M8: =AUXILIAR!D4 -> 891 | N8: =GETPIVOTDATA("Sobreviviente",AUXILIAR!$E$3) -> 109 | O8: =N8/M8 -> 0.12233446
M9: TOTAL HOMBRES | N9: HOMBRES SOBREVIVIENTES | O9: TASA DE SUP HOMBRES
M10: =AUXILIAR!D5 -> 577 | N10: =AUXILIAR!E5 -> 109 | O10: =N10/M10 -> 0.18890815
M11: TOTAL MUJERES | N11: MUJERES SOBREVIVIENTES | O11: TASA DE SUP MUJERES
M12: =AUXILIAR!D6 -> 314 | N12: =AUXILIAR!E6 -> 233 | O12: =N12/M12 -> 0.74203822
C35: Dashboard interactivo con segmentación dinámica y análisis multivariable
